<?xml version="1.0" encoding="UTF-8"?>
<testng-results ignored="0" total="8" passed="5" failed="3" skipped="0">
  <reporter-output>
  </reporter-output>
  <suite started-at="2025-05-14T14:49:58 EEST" name="SauseLabSuite" finished-at="2025-05-14T14:52:06 EEST" duration-ms="127934">
    <groups>
    </groups>
    <test started-at="2025-05-14T14:49:58 EEST" name="LoginTest" finished-at="2025-05-14T14:52:06 EEST" duration-ms="127934">
      <class name="Tests.TestLogin">
        <test-method is-config="true" signature="setUp()[pri:0, instance:Tests.TestLogin@f5958c9]" started-at="2025-05-14T14:49:58 EEST" name="setUp" finished-at="2025-05-14T14:50:17 EEST" duration-ms="18091" status="PASS">
          <reporter-output>
          </reporter-output>
        </test-method> <!-- setUp -->
        <test-method signature="TC_Login_005_testInvalidUsernameAndPassword()[pri:1, instance:Tests.TestLogin@f5958c9]" started-at="2025-05-14T14:50:17 EEST" name="TC_Login_005_testInvalidUsernameAndPassword" finished-at="2025-05-14T14:50:45 EEST" duration-ms="28168" status="FAIL">
          <exception class="java.lang.AssertionError">
            <message>
              <![CDATA[Login should be rejected for invalid credentials. expected [true] but found [false]]]>
            </message>
            <full-stacktrace>
              <![CDATA[java.lang.AssertionError: Login should be rejected for invalid credentials. expected [true] but found [false]
at org.testng.Assert.fail(Assert.java:110)
at org.testng.Assert.failNotEquals(Assert.java:1577)
at org.testng.Assert.assertTrue(Assert.java:56)
at Tests.TestLogin.TC_Login_005_testInvalidUsernameAndPassword(TestLogin.java:15)
at java.base/jdk.internal.reflect.DirectMethodHandleAccessor.invoke(DirectMethodHandleAccessor.java:103)
at java.base/java.lang.reflect.Method.invoke(Method.java:580)
at org.testng.internal.invokers.MethodInvocationHelper.invokeMethod(MethodInvocationHelper.java:139)
at org.testng.internal.invokers.TestInvoker.invokeMethod(TestInvoker.java:677)
at org.testng.internal.invokers.TestInvoker.invokeTestMethod(TestInvoker.java:221)
at org.testng.internal.invokers.MethodRunner.runInSequence(MethodRunner.java:50)
at org.testng.internal.invokers.TestInvoker$MethodInvocationAgent.invoke(TestInvoker.java:969)
at org.testng.internal.invokers.TestInvoker.invokeTestMethods(TestInvoker.java:194)
at org.testng.internal.invokers.TestMethodWorker.invokeTestMethods(TestMethodWorker.java:148)
at org.testng.internal.invokers.TestMethodWorker.run(TestMethodWorker.java:128)
at java.base/java.util.ArrayList.forEach(ArrayList.java:1596)
at org.testng.TestRunner.privateRun(TestRunner.java:829)
at org.testng.TestRunner.run(TestRunner.java:602)
at org.testng.SuiteRunner.runTest(SuiteRunner.java:437)
at org.testng.SuiteRunner.runSequentially(SuiteRunner.java:431)
at org.testng.SuiteRunner.privateRun(SuiteRunner.java:391)
at org.testng.SuiteRunner.run(SuiteRunner.java:330)
at org.testng.SuiteRunnerWorker.runSuite(SuiteRunnerWorker.java:52)
at org.testng.SuiteRunnerWorker.run(SuiteRunnerWorker.java:95)
at org.testng.TestNG.runSuitesSequentially(TestNG.java:1256)
at org.testng.TestNG.runSuitesLocally(TestNG.java:1176)
at org.testng.TestNG.runSuites(TestNG.java:1099)
at org.testng.TestNG.run(TestNG.java:1067)
at org.testng.remote.AbstractRemoteTestNG.run(AbstractRemoteTestNG.java:115)
at org.testng.remote.RemoteTestNG.initAndRun(RemoteTestNG.java:293)
at org.testng.remote.RemoteTestNG.main(RemoteTestNG.java:91)
]]>
            </full-stacktrace>
          </exception> <!-- java.lang.AssertionError -->
          <reporter-output>
          </reporter-output>
        </test-method> <!-- TC_Login_005_testInvalidUsernameAndPassword -->
        <test-method signature="TC_Login_001_testValidLogin()[pri:2, instance:Tests.TestLogin@f5958c9]" started-at="2025-05-14T14:50:45 EEST" name="TC_Login_001_testValidLogin" finished-at="2025-05-14T14:50:52 EEST" duration-ms="7540" status="PASS">
          <reporter-output>
          </reporter-output>
        </test-method> <!-- TC_Login_001_testValidLogin -->
        <test-method signature="TC_Login_008_testLockedUserLogin()[pri:3, instance:Tests.TestLogin@f5958c9]" started-at="2025-05-14T14:50:52 EEST" name="TC_Login_008_testLockedUserLogin" finished-at="2025-05-14T14:50:58 EEST" duration-ms="5867" status="PASS">
          <reporter-output>
          </reporter-output>
        </test-method> <!-- TC_Login_008_testLockedUserLogin -->
        <test-method signature="TC_Login_002_testEmptyUsernameAndPassword()[pri:4, instance:Tests.TestLogin@f5958c9]" started-at="2025-05-14T14:50:58 EEST" name="TC_Login_002_testEmptyUsernameAndPassword" finished-at="2025-05-14T14:51:04 EEST" duration-ms="6038" status="PASS">
          <reporter-output>
          </reporter-output>
        </test-method> <!-- TC_Login_002_testEmptyUsernameAndPassword -->
        <test-method signature="TC_Login_006_testInvalidUsername()[pri:5, instance:Tests.TestLogin@f5958c9]" started-at="2025-05-14T14:51:04 EEST" name="TC_Login_006_testInvalidUsername" finished-at="2025-05-14T14:51:29 EEST" duration-ms="25250" status="FAIL">
          <exception class="java.lang.AssertionError">
            <message>
              <![CDATA[Login should be rejected for invalid credentials. expected [true] but found [false]]]>
            </message>
            <full-stacktrace>
              <![CDATA[java.lang.AssertionError: Login should be rejected for invalid credentials. expected [true] but found [false]
at org.testng.Assert.fail(Assert.java:110)
at org.testng.Assert.failNotEquals(Assert.java:1577)
at org.testng.Assert.assertTrue(Assert.java:56)
at Tests.TestLogin.TC_Login_006_testInvalidUsername(TestLogin.java:51)
at java.base/jdk.internal.reflect.DirectMethodHandleAccessor.invoke(DirectMethodHandleAccessor.java:103)
at java.base/java.lang.reflect.Method.invoke(Method.java:580)
at org.testng.internal.invokers.MethodInvocationHelper.invokeMethod(MethodInvocationHelper.java:139)
at org.testng.internal.invokers.TestInvoker.invokeMethod(TestInvoker.java:677)
at org.testng.internal.invokers.TestInvoker.invokeTestMethod(TestInvoker.java:221)
at org.testng.internal.invokers.MethodRunner.runInSequence(MethodRunner.java:50)
at org.testng.internal.invokers.TestInvoker$MethodInvocationAgent.invoke(TestInvoker.java:969)
at org.testng.internal.invokers.TestInvoker.invokeTestMethods(TestInvoker.java:194)
at org.testng.internal.invokers.TestMethodWorker.invokeTestMethods(TestMethodWorker.java:148)
at org.testng.internal.invokers.TestMethodWorker.run(TestMethodWorker.java:128)
at java.base/java.util.ArrayList.forEach(ArrayList.java:1596)
at org.testng.TestRunner.privateRun(TestRunner.java:829)
at org.testng.TestRunner.run(TestRunner.java:602)
at org.testng.SuiteRunner.runTest(SuiteRunner.java:437)
at org.testng.SuiteRunner.runSequentially(SuiteRunner.java:431)
at org.testng.SuiteRunner.privateRun(SuiteRunner.java:391)
at org.testng.SuiteRunner.run(SuiteRunner.java:330)
at org.testng.SuiteRunnerWorker.runSuite(SuiteRunnerWorker.java:52)
at org.testng.SuiteRunnerWorker.run(SuiteRunnerWorker.java:95)
at org.testng.TestNG.runSuitesSequentially(TestNG.java:1256)
at org.testng.TestNG.runSuitesLocally(TestNG.java:1176)
at org.testng.TestNG.runSuites(TestNG.java:1099)
at org.testng.TestNG.run(TestNG.java:1067)
at org.testng.remote.AbstractRemoteTestNG.run(AbstractRemoteTestNG.java:115)
at org.testng.remote.RemoteTestNG.initAndRun(RemoteTestNG.java:293)
at org.testng.remote.RemoteTestNG.main(RemoteTestNG.java:91)
]]>
            </full-stacktrace>
          </exception> <!-- java.lang.AssertionError -->
          <reporter-output>
          </reporter-output>
        </test-method> <!-- TC_Login_006_testInvalidUsername -->
        <test-method signature="TC_Login_004_testEmptyPassword()[pri:6, instance:Tests.TestLogin@f5958c9]" started-at="2025-05-14T14:51:29 EEST" name="TC_Login_004_testEmptyPassword" finished-at="2025-05-14T14:51:35 EEST" duration-ms="5808" status="PASS">
          <reporter-output>
          </reporter-output>
        </test-method> <!-- TC_Login_004_testEmptyPassword -->
        <test-method signature="TC_Login_007_testInvalidPassword()[pri:7, instance:Tests.TestLogin@f5958c9]" started-at="2025-05-14T14:51:35 EEST" name="TC_Login_007_testInvalidPassword" finished-at="2025-05-14T14:52:01 EEST" duration-ms="25299" status="FAIL">
          <exception class="java.lang.AssertionError">
            <message>
              <![CDATA[Login should be rejected for invalid credentials. expected [true] but found [false]]]>
            </message>
            <full-stacktrace>
              <![CDATA[java.lang.AssertionError: Login should be rejected for invalid credentials. expected [true] but found [false]
at org.testng.Assert.fail(Assert.java:110)
at org.testng.Assert.failNotEquals(Assert.java:1577)
at org.testng.Assert.assertTrue(Assert.java:56)
at Tests.TestLogin.TC_Login_007_testInvalidPassword(TestLogin.java:69)
at java.base/jdk.internal.reflect.DirectMethodHandleAccessor.invoke(DirectMethodHandleAccessor.java:103)
at java.base/java.lang.reflect.Method.invoke(Method.java:580)
at org.testng.internal.invokers.MethodInvocationHelper.invokeMethod(MethodInvocationHelper.java:139)
at org.testng.internal.invokers.TestInvoker.invokeMethod(TestInvoker.java:677)
at org.testng.internal.invokers.TestInvoker.invokeTestMethod(TestInvoker.java:221)
at org.testng.internal.invokers.MethodRunner.runInSequence(MethodRunner.java:50)
at org.testng.internal.invokers.TestInvoker$MethodInvocationAgent.invoke(TestInvoker.java:969)
at org.testng.internal.invokers.TestInvoker.invokeTestMethods(TestInvoker.java:194)
at org.testng.internal.invokers.TestMethodWorker.invokeTestMethods(TestMethodWorker.java:148)
at org.testng.internal.invokers.TestMethodWorker.run(TestMethodWorker.java:128)
at java.base/java.util.ArrayList.forEach(ArrayList.java:1596)
at org.testng.TestRunner.privateRun(TestRunner.java:829)
at org.testng.TestRunner.run(TestRunner.java:602)
at org.testng.SuiteRunner.runTest(SuiteRunner.java:437)
at org.testng.SuiteRunner.runSequentially(SuiteRunner.java:431)
at org.testng.SuiteRunner.privateRun(SuiteRunner.java:391)
at org.testng.SuiteRunner.run(SuiteRunner.java:330)
at org.testng.SuiteRunnerWorker.runSuite(SuiteRunnerWorker.java:52)
at org.testng.SuiteRunnerWorker.run(SuiteRunnerWorker.java:95)
at org.testng.TestNG.runSuitesSequentially(TestNG.java:1256)
at org.testng.TestNG.runSuitesLocally(TestNG.java:1176)
at org.testng.TestNG.runSuites(TestNG.java:1099)
at org.testng.TestNG.run(TestNG.java:1067)
at org.testng.remote.AbstractRemoteTestNG.run(AbstractRemoteTestNG.java:115)
at org.testng.remote.RemoteTestNG.initAndRun(RemoteTestNG.java:293)
at org.testng.remote.RemoteTestNG.main(RemoteTestNG.java:91)
]]>
            </full-stacktrace>
          </exception> <!-- java.lang.AssertionError -->
          <reporter-output>
          </reporter-output>
        </test-method> <!-- TC_Login_007_testInvalidPassword -->
        <test-method signature="TC_Login_003_testEmptyUsername()[pri:8, instance:Tests.TestLogin@f5958c9]" started-at="2025-05-14T14:52:01 EEST" name="TC_Login_003_testEmptyUsername" finished-at="2025-05-14T14:52:06 EEST" duration-ms="5004" status="PASS">
          <reporter-output>
          </reporter-output>
        </test-method> <!-- TC_Login_003_testEmptyUsername -->
        <test-method is-config="true" signature="tearDown()[pri:0, instance:Tests.TestLogin@f5958c9]" started-at="2025-05-14T14:52:06 EEST" name="tearDown" finished-at="2025-05-14T14:52:06 EEST" duration-ms="753" status="PASS">
          <reporter-output>
          </reporter-output>
        </test-method> <!-- tearDown -->
      </class> <!-- Tests.TestLogin -->
    </test> <!-- LoginTest -->
  </suite> <!-- SauseLabSuite -->
</testng-results>
